<robot name = "robot">
    <material name="blue">
        <color rgba="0 0 1.0 1.0"/>
    </material>
    <material name="green">
        <color rgba="0 1.0 0 1.0"/>
    </material>
    <link name="Cube0">
        <inertial>
            <origin xyz="0 0 0.6341685254570111" rpy="0 0 0"/>
            <mass value="1" />
            <inertia ixx="100" ixy="0" ixz="0" iyy="100" iyz="0" izz="100" />
        </inertial>
        <visual>
            <origin xyz="0 0 0.6341685254570111" rpy="0 0 0"/>
            <geometry>
                <box size="0.84904386910402 0.6616318779042362 1.2683370509140222" />
            </geometry>
    <material name="green"/>
        </visual>
        <collision>
            <origin xyz="0 0 0.6341685254570111" rpy="0 0 0"/>
            <geometry>
                <box size="0.84904386910402 0.6616318779042362 1.2683370509140222" />
            </geometry>
        </collision>
    </link>
    <joint name="Cube0_Cube1" type="revolute">
       <parent link="Cube0"/>
       <child  link="Cube1"/>
       <origin rpy="0 0 0" xyz="-0.0 -0.8742147199097677 -0.0" />
       <axis xyz="1 0 0"/>
       <limit effort="0.0" lower="-3.14159" upper="3.14159" velocity="0.0"/>
    </joint>
    <link name="Cube1">
        <inertial>
            <origin xyz="0 0 0.6257922158966023" rpy="0 0 0"/>
            <mass value="1" />
            <inertia ixx="100" ixy="0" ixz="0" iyy="100" iyz="0" izz="100" />
        </inertial>
        <visual>
            <origin xyz="0 0 0.6257922158966023" rpy="0 0 0"/>
            <geometry>
                <box size="0.6300411485268356 0.8742147199097677 1.2515844317932046" />
            </geometry>
    <material name="blue"/>
        </visual>
        <collision>
            <origin xyz="0 0 0.6257922158966023" rpy="0 0 0"/>
            <geometry>
                <box size="0.6300411485268356 0.8742147199097677 1.2515844317932046" />
            </geometry>
        </collision>
    </link>
    <joint name="Cube0_Cube2" type="revolute">
       <parent link="Cube0"/>
       <child  link="Cube2"/>
       <origin rpy="0 0 0" xyz="-0.0 -0.0 1.254440425420498" />
       <axis xyz="1 0 0"/>
       <limit effort="0.0" lower="-3.14159" upper="3.14159" velocity="0.0"/>
    </joint>
    <link name="Cube2">
        <inertial>
            <origin xyz="0 0 0.627220212710249" rpy="0 0 0"/>
            <mass value="1" />
            <inertia ixx="100" ixy="0" ixz="0" iyy="100" iyz="0" izz="100" />
        </inertial>
        <visual>
            <origin xyz="0 0 0.627220212710249" rpy="0 0 0"/>
            <geometry>
                <box size="0.5962410535917851 1.1560291499627384 1.254440425420498" />
            </geometry>
    <material name="green"/>
        </visual>
        <collision>
            <origin xyz="0 0 0.627220212710249" rpy="0 0 0"/>
            <geometry>
                <box size="0.5962410535917851 1.1560291499627384 1.254440425420498" />
            </geometry>
        </collision>
    </link>
    <joint name="Cube1_Cube3" type="revolute">
       <parent link="Cube1"/>
       <child  link="Cube3"/>
       <origin rpy="0 0 0" xyz="-0.0 -0.0 -1.3801180749405597" />
       <axis xyz="1 0 0"/>
       <limit effort="0.0" lower="-3.14159" upper="3.14159" velocity="0.0"/>
    </joint>
    <link name="Cube3">
        <inertial>
            <origin xyz="0 0 0.6900590374702799" rpy="0 0 0"/>
            <mass value="1" />
            <inertia ixx="100" ixy="0" ixz="0" iyy="100" iyz="0" izz="100" />
        </inertial>
        <visual>
            <origin xyz="0 0 0.6900590374702799" rpy="0 0 0"/>
            <geometry>
                <box size="1.0442304906746438 0.8084203044039545 1.3801180749405597" />
            </geometry>
    <material name="green"/>
        </visual>
        <collision>
            <origin xyz="0 0 0.6900590374702799" rpy="0 0 0"/>
            <geometry>
                <box size="1.0442304906746438 0.8084203044039545 1.3801180749405597" />
            </geometry>
        </collision>
    </link>
    <joint name="Cube0_Cube4" type="revolute">
       <parent link="Cube0"/>
       <child  link="Cube4"/>
       <origin rpy="0 0 0" xyz="-0.0 -0.0 -0.6288965528947907" />
       <axis xyz="1 0 0"/>
       <limit effort="0.0" lower="-3.14159" upper="3.14159" velocity="0.0"/>
    </joint>
    <link name="Cube4">
        <inertial>
            <origin xyz="0 0 0.31444827644739537" rpy="0 0 0"/>
            <mass value="1" />
            <inertia ixx="100" ixy="0" ixz="0" iyy="100" iyz="0" izz="100" />
        </inertial>
        <visual>
            <origin xyz="0 0 0.31444827644739537" rpy="0 0 0"/>
            <geometry>
                <box size="1.0446107970413472 0.6234655258229708 0.6288965528947907" />
            </geometry>
    <material name="blue"/>
        </visual>
        <collision>
            <origin xyz="0 0 0.31444827644739537" rpy="0 0 0"/>
            <geometry>
                <box size="1.0446107970413472 0.6234655258229708 0.6288965528947907" />
            </geometry>
        </collision>
    </link>
    <joint name="Cube0_Cube5" type="revolute">
       <parent link="Cube0"/>
       <child  link="Cube5"/>
       <origin rpy="0 0 0" xyz="-0.8860765068346297 -0.0 -0.0" />
       <axis xyz="1 0 0"/>
       <limit effort="0.0" lower="-3.14159" upper="3.14159" velocity="0.0"/>
    </joint>
    <link name="Cube5">
        <inertial>
            <origin xyz="0 0 0.6658017670654826" rpy="0 0 0"/>
            <mass value="1" />
            <inertia ixx="100" ixy="0" ixz="0" iyy="100" iyz="0" izz="100" />
        </inertial>
        <visual>
            <origin xyz="0 0 0.6658017670654826" rpy="0 0 0"/>
            <geometry>
                <box size="0.8860765068346297 0.8898322427158593 1.331603534130965" />
            </geometry>
    <material name="blue"/>
        </visual>
        <collision>
            <origin xyz="0 0 0.6658017670654826" rpy="0 0 0"/>
            <geometry>
                <box size="0.8860765068346297 0.8898322427158593 1.331603534130965" />
            </geometry>
        </collision>
    </link>
</robot>