<robot name = "robot">
    <material name="blue">
        <color rgba="0 0 1.0 1.0"/>
    </material>
    <material name="green">
        <color rgba="0 1.0 0 1.0"/>
    </material>
    <link name="Cube0">
        <inertial>
            <origin xyz="0 0 1.443961905555287" rpy="0 0 0"/>
            <mass value="1" />
            <inertia ixx="100" ixy="0" ixz="0" iyy="100" iyz="0" izz="100" />
        </inertial>
        <visual>
            <origin xyz="0 0 1.443961905555287" rpy="0 0 0"/>
            <geometry>
                <box size="1.2061091339124892 1.1681133373044195 0.6117615489816307" />
            </geometry>
    <material name="green"/>
        </visual>
        <collision>
            <origin xyz="0 0 1.443961905555287" rpy="0 0 0"/>
            <geometry>
                <box size="1.2061091339124892 1.1681133373044195 0.6117615489816307" />
            </geometry>
        </collision>
    </link>
    <joint name="Cube0_Cube1" type="revolute">
       <parent link="Cube0"/>
       <child  link="Cube1"/>
       <origin rpy="0 0 0" xyz="1.2061091339124892 0 0" />
       <axis xyz="1 0 0"/>
       <limit effort="0.0" lower="-3.14159" upper="3.14159" velocity="0.0"/>
    </joint>
    <link name="Cube1">
        <inertial>
            <origin xyz="0 0 0.7219809527776435" rpy="0 0 0"/>
            <mass value="1" />
            <inertia ixx="100" ixy="0" ixz="0" iyy="100" iyz="0" izz="100" />
        </inertial>
        <visual>
            <origin xyz="0 0 0.7219809527776435" rpy="0 0 0"/>
            <geometry>
                <box size="0.5504521719972292 1.0360730580366457 0.9223179336096364" />
            </geometry>
    <material name="blue"/>
        </visual>
        <collision>
            <origin xyz="0 0 0.7219809527776435" rpy="0 0 0"/>
            <geometry>
                <box size="0.5504521719972292 1.0360730580366457 0.9223179336096364" />
            </geometry>
        </collision>
    </link>
    <joint name="Cube1_Cube2" type="revolute">
       <parent link="Cube1"/>
       <child  link="Cube2"/>
       <origin rpy="0 0 0" xyz="0 0 -0.9223179336096364" />
       <axis xyz="1 0 0"/>
       <limit effort="0.0" lower="-3.14159" upper="3.14159" velocity="0.0"/>
    </joint>
    <link name="Cube2">
        <inertial>
            <origin xyz="0 0 0.7219809527776435" rpy="0 0 0"/>
            <mass value="1" />
            <inertia ixx="100" ixy="0" ixz="0" iyy="100" iyz="0" izz="100" />
        </inertial>
        <visual>
            <origin xyz="0 0 0.7219809527776435" rpy="0 0 0"/>
            <geometry>
                <box size="0.7297897198399328 1.2450221332714992 1.3625506835184455" />
            </geometry>
    <material name="blue"/>
        </visual>
        <collision>
            <origin xyz="0 0 0.7219809527776435" rpy="0 0 0"/>
            <geometry>
                <box size="0.7297897198399328 1.2450221332714992 1.3625506835184455" />
            </geometry>
        </collision>
    </link>
    <joint name="Cube1_Cube3" type="revolute">
       <parent link="Cube1"/>
       <child  link="Cube3"/>
       <origin rpy="0 0 0" xyz="-0.5504521719972292 0 0" />
       <axis xyz="1 0 0"/>
       <limit effort="0.0" lower="-3.14159" upper="3.14159" velocity="0.0"/>
    </joint>
    <link name="Cube3">
        <inertial>
            <origin xyz="0 0 0.7219809527776435" rpy="0 0 0"/>
            <mass value="1" />
            <inertia ixx="100" ixy="0" ixz="0" iyy="100" iyz="0" izz="100" />
        </inertial>
        <visual>
            <origin xyz="0 0 0.7219809527776435" rpy="0 0 0"/>
            <geometry>
                <box size="1.4599033381265536 1.2801248341404778 1.0034428448791073" />
            </geometry>
    <material name="green"/>
        </visual>
        <collision>
            <origin xyz="0 0 0.7219809527776435" rpy="0 0 0"/>
            <geometry>
                <box size="1.4599033381265536 1.2801248341404778 1.0034428448791073" />
            </geometry>
        </collision>
    </link>
    <joint name="Cube0_Cube4" type="revolute">
       <parent link="Cube0"/>
       <child  link="Cube4"/>
       <origin rpy="0 0 0" xyz="-1.2061091339124892 0 0" />
       <axis xyz="1 0 0"/>
       <limit effort="0.0" lower="-3.14159" upper="3.14159" velocity="0.0"/>
    </joint>
    <link name="Cube4">
        <inertial>
            <origin xyz="0 0 0.7219809527776435" rpy="0 0 0"/>
            <mass value="1" />
            <inertia ixx="100" ixy="0" ixz="0" iyy="100" iyz="0" izz="100" />
        </inertial>
        <visual>
            <origin xyz="0 0 0.7219809527776435" rpy="0 0 0"/>
            <geometry>
                <box size="1.1090060144054719 1.316839192033532 1.443961905555287" />
            </geometry>
    <material name="green"/>
        </visual>
        <collision>
            <origin xyz="0 0 0.7219809527776435" rpy="0 0 0"/>
            <geometry>
                <box size="1.1090060144054719 1.316839192033532 1.443961905555287" />
            </geometry>
        </collision>
    </link>
    <joint name="Cube1_Cube5" type="revolute">
       <parent link="Cube1"/>
       <child  link="Cube5"/>
       <origin rpy="0 0 0" xyz="-0.5504521719972292 0 0" />
       <axis xyz="1 0 0"/>
       <limit effort="0.0" lower="-3.14159" upper="3.14159" velocity="0.0"/>
    </joint>
    <link name="Cube5">
        <inertial>
            <origin xyz="0 0 0.7219809527776435" rpy="0 0 0"/>
            <mass value="1" />
            <inertia ixx="100" ixy="0" ixz="0" iyy="100" iyz="0" izz="100" />
        </inertial>
        <visual>
            <origin xyz="0 0 0.7219809527776435" rpy="0 0 0"/>
            <geometry>
                <box size="1.3735136643540637 0.6115795554415795 0.5857717564878926" />
            </geometry>
    <material name="green"/>
        </visual>
        <collision>
            <origin xyz="0 0 0.7219809527776435" rpy="0 0 0"/>
            <geometry>
                <box size="1.3735136643540637 0.6115795554415795 0.5857717564878926" />
            </geometry>
        </collision>
    </link>
    <joint name="Cube2_Cube6" type="revolute">
       <parent link="Cube2"/>
       <child  link="Cube6"/>
       <origin rpy="0 0 0" xyz="0 0 -1.3625506835184455" />
       <axis xyz="1 0 0"/>
       <limit effort="0.0" lower="-3.14159" upper="3.14159" velocity="0.0"/>
    </joint>
    <link name="Cube6">
        <inertial>
            <origin xyz="0 0 0.7219809527776435" rpy="0 0 0"/>
            <mass value="1" />
            <inertia ixx="100" ixy="0" ixz="0" iyy="100" iyz="0" izz="100" />
        </inertial>
        <visual>
            <origin xyz="0 0 0.7219809527776435" rpy="0 0 0"/>
            <geometry>
                <box size="0.7727947880941977 1.1825358898406702 1.0573853315511754" />
            </geometry>
    <material name="green"/>
        </visual>
        <collision>
            <origin xyz="0 0 0.7219809527776435" rpy="0 0 0"/>
            <geometry>
                <box size="0.7727947880941977 1.1825358898406702 1.0573853315511754" />
            </geometry>
        </collision>
    </link>
    <joint name="Cube6_Cube7" type="revolute">
       <parent link="Cube6"/>
       <child  link="Cube7"/>
       <origin rpy="0 0 0" xyz="0 1.1825358898406702 0" />
       <axis xyz="1 0 0"/>
       <limit effort="0.0" lower="-3.14159" upper="3.14159" velocity="0.0"/>
    </joint>
    <link name="Cube7">
        <inertial>
            <origin xyz="0 0 0.7219809527776435" rpy="0 0 0"/>
            <mass value="1" />
            <inertia ixx="100" ixy="0" ixz="0" iyy="100" iyz="0" izz="100" />
        </inertial>
        <visual>
            <origin xyz="0 0 0.7219809527776435" rpy="0 0 0"/>
            <geometry>
                <box size="1.1146218885423036 1.4228518478201826 1.3188469511711094" />
            </geometry>
    <material name="blue"/>
        </visual>
        <collision>
            <origin xyz="0 0 0.7219809527776435" rpy="0 0 0"/>
            <geometry>
                <box size="1.1146218885423036 1.4228518478201826 1.3188469511711094" />
            </geometry>
        </collision>
    </link>
</robot>