<robot name = "robot">
    <material name="blue">
        <color rgba="0 0 1.0 1.0"/>
    </material>
    <material name="green">
        <color rgba="0 1.0 0 1.0"/>
    </material>
    <link name="Cube0">
        <inertial>
            <origin xyz="0 0 1.5" rpy="0 0 0"/>
            <mass value="1" />
            <inertia ixx="100" ixy="0" ixz="0" iyy="100" iyz="0" izz="100" />
        </inertial>
        <visual>
            <origin xyz="0 0 1.5" rpy="0 0 0"/>
            <geometry>
                <box size="1.2 2.6 2.4" />
            </geometry>
    <material name="blue"/>
        </visual>
        <collision>
            <origin xyz="0 0 1.5" rpy="0 0 0"/>
            <geometry>
                <box size="1.2 2.6 2.4" />
            </geometry>
        </collision>
    </link>
    <joint name="Cube0_Cube1" type="revolute">
       <parent link="Cube0"/>
       <child  link="Cube1"/>
       <origin rpy="0 0 0" xyz="0 1.3 0" />
       <axis xyz="1 0 0"/>
       <limit effort="0.0" lower="-3.14159" upper="3.14159" velocity="0.0"/>
    </joint>
    <link name="Cube1">
        <inertial>
            <origin xyz="0 1.2 1.5" rpy="0 0 0"/>
            <mass value="1" />
            <inertia ixx="100" ixy="0" ixz="0" iyy="100" iyz="0" izz="100" />
        </inertial>
        <visual>
            <origin xyz="0 1.2 1.5" rpy="0 0 0"/>
            <geometry>
                <box size="2.6 2.4 2.4" />
            </geometry>
    <material name="blue"/>
        </visual>
        <collision>
            <origin xyz="0 1.2 1.5" rpy="0 0 0"/>
            <geometry>
                <box size="2.6 2.4 2.4" />
            </geometry>
        </collision>
    </link>
    <joint name="Cube1_Cube2" type="revolute">
       <parent link="Cube1"/>
       <child  link="Cube2"/>
       <origin rpy="0 0 0" xyz="0 2.4 0" />
       <axis xyz="1 0 0"/>
       <limit effort="0.0" lower="-3.14159" upper="3.14159" velocity="0.0"/>
    </joint>
    <link name="Cube2">
        <inertial>
            <origin xyz="0 1.3 1.5" rpy="0 0 0"/>
            <mass value="1" />
            <inertia ixx="100" ixy="0" ixz="0" iyy="100" iyz="0" izz="100" />
        </inertial>
        <visual>
            <origin xyz="0 1.3 1.5" rpy="0 0 0"/>
            <geometry>
                <box size="1.2 2.6 3.0" />
            </geometry>
    <material name="green"/>
        </visual>
        <collision>
            <origin xyz="0 1.3 1.5" rpy="0 0 0"/>
            <geometry>
                <box size="1.2 2.6 3.0" />
            </geometry>
        </collision>
    </link>
    <joint name="Cube2_Cube3" type="revolute">
       <parent link="Cube2"/>
       <child  link="Cube3"/>
       <origin rpy="0 0 0" xyz="0 2.6 0" />
       <axis xyz="1 0 0"/>
       <limit effort="0.0" lower="-3.14159" upper="3.14159" velocity="0.0"/>
    </joint>
    <link name="Cube3">
        <inertial>
            <origin xyz="0 0.9 1.5" rpy="0 0 0"/>
            <mass value="1" />
            <inertia ixx="100" ixy="0" ixz="0" iyy="100" iyz="0" izz="100" />
        </inertial>
        <visual>
            <origin xyz="0 0.9 1.5" rpy="0 0 0"/>
            <geometry>
                <box size="1.2 1.8 1.6" />
            </geometry>
    <material name="green"/>
        </visual>
        <collision>
            <origin xyz="0 0.9 1.5" rpy="0 0 0"/>
            <geometry>
                <box size="1.2 1.8 1.6" />
            </geometry>
        </collision>
    </link>
    <joint name="Cube3_Cube4" type="revolute">
       <parent link="Cube3"/>
       <child  link="Cube4"/>
       <origin rpy="0 0 0" xyz="0 1.8 0" />
       <axis xyz="1 0 0"/>
       <limit effort="0.0" lower="-3.14159" upper="3.14159" velocity="0.0"/>
    </joint>
    <link name="Cube4">
        <inertial>
            <origin xyz="0 1.3 1.5" rpy="0 0 0"/>
            <mass value="1" />
            <inertia ixx="100" ixy="0" ixz="0" iyy="100" iyz="0" izz="100" />
        </inertial>
        <visual>
            <origin xyz="0 1.3 1.5" rpy="0 0 0"/>
            <geometry>
                <box size="1.2 2.6 2.6" />
            </geometry>
    <material name="blue"/>
        </visual>
        <collision>
            <origin xyz="0 1.3 1.5" rpy="0 0 0"/>
            <geometry>
                <box size="1.2 2.6 2.6" />
            </geometry>
        </collision>
    </link>
    <joint name="Cube4_Cube5" type="revolute">
       <parent link="Cube4"/>
       <child  link="Cube5"/>
       <origin rpy="0 0 0" xyz="0 2.6 0" />
       <axis xyz="1 0 0"/>
       <limit effort="0.0" lower="-3.14159" upper="3.14159" velocity="0.0"/>
    </joint>
    <link name="Cube5">
        <inertial>
            <origin xyz="0 1.5 1.5" rpy="0 0 0"/>
            <mass value="1" />
            <inertia ixx="100" ixy="0" ixz="0" iyy="100" iyz="0" izz="100" />
        </inertial>
        <visual>
            <origin xyz="0 1.5 1.5" rpy="0 0 0"/>
            <geometry>
                <box size="2.0 3.0 3.0" />
            </geometry>
    <material name="green"/>
        </visual>
        <collision>
            <origin xyz="0 1.5 1.5" rpy="0 0 0"/>
            <geometry>
                <box size="2.0 3.0 3.0" />
            </geometry>
        </collision>
    </link>
</robot>