<robot name = "robot">
    <material name="blue">
        <color rgba="0 0 1.0 1.0"/>
    </material>
    <material name="green">
        <color rgba="0 1.0 0 1.0"/>
    </material>
    <link name="Cube0">
        <inertial>
            <origin xyz="0 0 1.2861275480575456" rpy="0 0 0"/>
            <mass value="1" />
            <inertia ixx="100" ixy="0" ixz="0" iyy="100" iyz="0" izz="100" />
        </inertial>
        <visual>
            <origin xyz="0 0 1.2861275480575456" rpy="0 0 0"/>
            <geometry>
                <box size="1.2273821388761017 1.0677780656362548 0.8542440863595545" />
            </geometry>
    <material name="green"/>
        </visual>
        <collision>
            <origin xyz="0 0 1.2861275480575456" rpy="0 0 0"/>
            <geometry>
                <box size="1.2273821388761017 1.0677780656362548 0.8542440863595545" />
            </geometry>
        </collision>
    </link>
    <joint name="Cube0_Cube1" type="revolute">
       <parent link="Cube0"/>
       <child  link="Cube1"/>
       <origin rpy="0 0 0" xyz="0 -1.0677780656362548 0" />
       <axis xyz="1 0 0"/>
       <limit effort="0.0" lower="-3.14159" upper="3.14159" velocity="0.0"/>
    </joint>
    <link name="Cube1">
        <inertial>
            <origin xyz="0 0 0.6430637740287728" rpy="0 0 0"/>
            <mass value="1" />
            <inertia ixx="100" ixy="0" ixz="0" iyy="100" iyz="0" izz="100" />
        </inertial>
        <visual>
            <origin xyz="0 0 0.6430637740287728" rpy="0 0 0"/>
            <geometry>
                <box size="0.6078500277440819 1.407118169673336 0.5847232950220143" />
            </geometry>
    <material name="green"/>
        </visual>
        <collision>
            <origin xyz="0 0 0.6430637740287728" rpy="0 0 0"/>
            <geometry>
                <box size="0.6078500277440819 1.407118169673336 0.5847232950220143" />
            </geometry>
        </collision>
    </link>
    <joint name="Cube1_Cube2" type="revolute">
       <parent link="Cube1"/>
       <child  link="Cube2"/>
       <origin rpy="0 0 0" xyz="0 -1.407118169673336 0" />
       <axis xyz="1 0 0"/>
       <limit effort="0.0" lower="-3.14159" upper="3.14159" velocity="0.0"/>
    </joint>
    <link name="Cube2">
        <inertial>
            <origin xyz="0 0 0.6430637740287728" rpy="0 0 0"/>
            <mass value="1" />
            <inertia ixx="100" ixy="0" ixz="0" iyy="100" iyz="0" izz="100" />
        </inertial>
        <visual>
            <origin xyz="0 0 0.6430637740287728" rpy="0 0 0"/>
            <geometry>
                <box size="1.132454104937534 0.5021736237319693 1.0575636406475568" />
            </geometry>
    <material name="green"/>
        </visual>
        <collision>
            <origin xyz="0 0 0.6430637740287728" rpy="0 0 0"/>
            <geometry>
                <box size="1.132454104937534 0.5021736237319693 1.0575636406475568" />
            </geometry>
        </collision>
    </link>
    <joint name="Cube2_Cube3" type="revolute">
       <parent link="Cube2"/>
       <child  link="Cube3"/>
       <origin rpy="0 0 0" xyz="-1.132454104937534 0 0" />
       <axis xyz="1 0 0"/>
       <limit effort="0.0" lower="-3.14159" upper="3.14159" velocity="0.0"/>
    </joint>
    <link name="Cube3">
        <inertial>
            <origin xyz="0 0 0.6430637740287728" rpy="0 0 0"/>
            <mass value="1" />
            <inertia ixx="100" ixy="0" ixz="0" iyy="100" iyz="0" izz="100" />
        </inertial>
        <visual>
            <origin xyz="0 0 0.6430637740287728" rpy="0 0 0"/>
            <geometry>
                <box size="0.9134831481567219 0.8475281094460102 1.020857810997415" />
            </geometry>
    <material name="blue"/>
        </visual>
        <collision>
            <origin xyz="0 0 0.6430637740287728" rpy="0 0 0"/>
            <geometry>
                <box size="0.9134831481567219 0.8475281094460102 1.020857810997415" />
            </geometry>
        </collision>
    </link>
    <joint name="Cube3_Cube4" type="revolute">
       <parent link="Cube3"/>
       <child  link="Cube4"/>
       <origin rpy="0 0 0" xyz="-0.9134831481567219 0 0" />
       <axis xyz="1 0 0"/>
       <limit effort="0.0" lower="-3.14159" upper="3.14159" velocity="0.0"/>
    </joint>
    <link name="Cube4">
        <inertial>
            <origin xyz="0 0 0.6430637740287728" rpy="0 0 0"/>
            <mass value="1" />
            <inertia ixx="100" ixy="0" ixz="0" iyy="100" iyz="0" izz="100" />
        </inertial>
        <visual>
            <origin xyz="0 0 0.6430637740287728" rpy="0 0 0"/>
            <geometry>
                <box size="1.3639849403921067 0.953491941370818 1.2861275480575456" />
            </geometry>
    <material name="blue"/>
        </visual>
        <collision>
            <origin xyz="0 0 0.6430637740287728" rpy="0 0 0"/>
            <geometry>
                <box size="1.3639849403921067 0.953491941370818 1.2861275480575456" />
            </geometry>
        </collision>
    </link>
    <joint name="Cube4_Cube5" type="revolute">
       <parent link="Cube4"/>
       <child  link="Cube5"/>
       <origin rpy="0 0 0" xyz="0 0 1.2861275480575456" />
       <axis xyz="1 0 0"/>
       <limit effort="0.0" lower="-3.14159" upper="3.14159" velocity="0.0"/>
    </joint>
    <link name="Cube5">
        <inertial>
            <origin xyz="0 0 0.6430637740287728" rpy="0 0 0"/>
            <mass value="1" />
            <inertia ixx="100" ixy="0" ixz="0" iyy="100" iyz="0" izz="100" />
        </inertial>
        <visual>
            <origin xyz="0 0 0.6430637740287728" rpy="0 0 0"/>
            <geometry>
                <box size="1.132855008560607 0.6907908360449134 1.0333179048110601" />
            </geometry>
    <material name="green"/>
        </visual>
        <collision>
            <origin xyz="0 0 0.6430637740287728" rpy="0 0 0"/>
            <geometry>
                <box size="1.132855008560607 0.6907908360449134 1.0333179048110601" />
            </geometry>
        </collision>
    </link>
    <joint name="Cube5_Cube6" type="revolute">
       <parent link="Cube5"/>
       <child  link="Cube6"/>
       <origin rpy="0 0 0" xyz="0 -0.6907908360449134 0" />
       <axis xyz="1 0 0"/>
       <limit effort="0.0" lower="-3.14159" upper="3.14159" velocity="0.0"/>
    </joint>
    <link name="Cube6">
        <inertial>
            <origin xyz="0 0 0.6430637740287728" rpy="0 0 0"/>
            <mass value="1" />
            <inertia ixx="100" ixy="0" ixz="0" iyy="100" iyz="0" izz="100" />
        </inertial>
        <visual>
            <origin xyz="0 0 0.6430637740287728" rpy="0 0 0"/>
            <geometry>
                <box size="1.0899031214099404 0.960797254468928 0.8234640438461336" />
            </geometry>
    <material name="blue"/>
        </visual>
        <collision>
            <origin xyz="0 0 0.6430637740287728" rpy="0 0 0"/>
            <geometry>
                <box size="1.0899031214099404 0.960797254468928 0.8234640438461336" />
            </geometry>
        </collision>
    </link>
</robot>